<?xml version="1.0" ?>
<sdf version="1.6">
  <model name="simple_arm">
    <plugin
      filename="gz-sim-joint-state-publisher-system"
      name="gz::sim::systems::JointStatePublisher">
    </plugin>

    <link name="base_link">
      <inertial>
        <mass>1</mass>
        <inertia>
          <ixx>0.02</ixx>
          <iyy>0.02</iyy>
          <izz>0.02</izz>
        </inertia>
      </inertial>
      <visual name="visual">
        <geometry>
          <cylinder>
            <radius>0.2</radius>
            <length>0.2</length>
          </cylinder>
        </geometry>
        <material>
          <ambient>0 0 0.8 1</ambient>
          <diffuse>0 0 0.8 1</diffuse>
        </material>
      </visual>
      <collision name="collision">
        <geometry>
          <cylinder>
            <radius>0.2</radius>
            <length>0.2</length>
          </cylinder>
        </geometry>
      </collision>
    </link>

    <link name="link1">
      <pose>0 0 0.35 0 0 0</pose>
      <inertial>
        <mass>1</mass>
        <pose>0 0 0.25 0 0 0</pose>
        <inertia>
          <ixx>0.02</ixx>
          <iyy>0.02</iyy>
          <izz>0.01</izz>
        </inertia>
      </inertial>
      <visual name="visual">
        <pose>0 0 0.25 0 0 0</pose>
        <geometry>
          <box>
            <size>0.1 0.1 0.5</size>
          </box>
        </geometry>
        <material>
          <ambient>0.8 0 0 1</ambient>
          <diffuse>0.8 0 0 1</diffuse>
        </material>
      </visual>
      <collision name="collision">
        <pose>0 0 0.25 0 0 0</pose>
        <geometry>
          <box>
            <size>0.1 0.1 0.5</size>
          </box>
        </geometry>
      </collision>
    </link>

    <joint name="joint1" type="revolute">
      <parent>base_link</parent>
      <child>link1</child>
      <pose>0 0 0 0 0 0</pose>
      <axis>
        <xyz>0 0 1</xyz>
        <limit>
          <lower>-3.14</lower>
          <upper>3.14</upper>
          <effort>100</effort>
          <velocity>100</velocity>
        </limit>
        <dynamics>
          <damping>0.1</damping>
        </dynamics>
      </axis>
    </joint>

    <link name="link2">
      <pose>0 0 0.85 0 0 0</pose>
      <inertial>
        <mass>1</mass>
        <pose>0 0 0.25 0 0 0</pose>
        <inertia>
          <ixx>0.02</ixx>
          <iyy>0.02</iyy>
          <izz>0.01</izz>
        </inertia>
      </inertial>
      <visual name="visual">
        <pose>0 0 0.25 0 0 0</pose>
        <geometry>
          <box>
            <size>0.1 0.1 0.5</size>
          </box>
        </geometry>
        <material>
          <ambient>0 0.8 0 1</ambient>
          <diffuse>0 0.8 0 1</diffuse>
        </material>
      </visual>
      <collision name="collision">
        <pose>0 0 0.25 0 0 0</pose>
        <geometry>
          <box>
            <size>0.1 0.1 0.5</size>
          </box>
        </geometry>
      </collision>
    </link>

    <joint name="joint2" type="revolute">
      <parent>link1</parent>
      <child>link2</child>
      <pose>0 0 0 0 0 0</pose>
      <axis>
        <xyz>0 1 0</xyz>
        <limit>
          <lower>-3.14</lower>
          <upper>3.14</upper>
          <effort>100</effort>
          <velocity>100</velocity>
        </limit>
        <dynamics>
          <damping>0.1</damping>
        </dynamics>
      </axis>
    </joint>

    <link name="link3">
      <pose>0 0 1.35 0 0 0</pose>
      <inertial>
        <mass>0.5</mass>
        <pose>0 0 0.1 0 0 0</pose>
        <inertia>
          <ixx>0.01</ixx>
          <iyy>0.01</iyy>
          <izz>0.005</izz>
        </inertia>
      </inertial>
      <visual name="visual">
        <pose>0 0 0.1 0 0 0</pose>
        <geometry>
          <box>
            <size>0.1 0.1 0.2</size>
          </box>
        </geometry>
        <material>
          <ambient>0 0 0.8 1</ambient>
          <diffuse>0 0 0.8 1</diffuse>
        </material>
      </visual>
      <collision name="collision">
        <pose>0 0 0.1 0 0 0</pose>
        <geometry>
          <box>
            <size>0.1 0.1 0.2</size>
          </box>
        </geometry>
      </collision>
    </link>

    <joint name="joint3" type="revolute">
      <parent>link2</parent>
      <child>link3</child>
      <pose>0 0 0 0 0 0</pose>
      <axis>
        <xyz>0 1 0</xyz>
        <limit>
          <lower>-3.14</lower>
          <upper>3.14</upper>
          <effort>100</effort>
          <velocity>100</velocity>
        </limit>
        <dynamics>
          <damping>0.1</damping>
        </dynamics>
      </axis>
    </joint>
  </model>
</sdf>