<?xml version="1.0"?>
<robot xmlns:xacro="http://www.ros.org/wiki/xacro">
    <!-- Cable macro for CDPR -->
    <xacro:macro name="cable_macro" params="prefix base_point platform_point parent child">
        <!-- Virtual link for cable -->
        <link name="${prefix}_link">
            <visual>
                <geometry>
                    <cylinder radius="${cable_radius}" length="${cable_max_length}"/>
                </geometry>
                <material name="cable_material">
                    <color rgba="0.8 0.8 0.8 1"/>
                </material>
            </visual>
            <inertial>
                <!-- Near-zero mass for cable -->
                <mass value="0.001"/>
                <inertia ixx="0.001" ixy="0" ixz="0" iyy="0.001" iyz="0" izz="0.001"/>
            </inertial>
        </link>

        <!-- Universal joint at base -->
        <joint name="${prefix}_base_joint" type="universal">
            <parent link="${parent}"/>
            <child link="${prefix}_link"/>
            <origin xyz="${base_point}" rpy="0 0 0"/>
            <axis xyz="1 0 0"/>
            <axis2 xyz="0 1 0"/>
            <dynamics damping="0.1" friction="0.1"/>
        </joint>

        <!-- Prismatic joint for cable extension -->
        <joint name="${prefix}_extension" type="prismatic">
            <parent link="${prefix}_link"/>
            <child link="${prefix}_end_link"/>
            <origin xyz="0 0 0" rpy="0 0 0"/>
            <axis xyz="0 0 1"/>
            <limit lower="0" upper="${cable_max_length}" 
                   effort="${cable_max_tension}" velocity="${cable_max_velocity}"/>
            <dynamics damping="0.1" friction="0.1"/>
        </joint>

        <!-- Virtual end link -->
        <link name="${prefix}_end_link">
            <inertial>
                <mass value="0.001"/>
                <inertia ixx="0.001" ixy="0" ixz="0" iyy="0.001" iyz="0" izz="0.001"/>
            </inertial>
        </link>

        <!-- Spherical joint at platform -->
        <joint name="${prefix}_platform_joint" type="spherical">
            <parent link="${prefix}_end_link"/>
            <child link="${child}"/>
            <origin xyz="${platform_point}" rpy="0 0 0"/>
            <dynamics damping="0.1" friction="0.1"/>
        </joint>

        <!-- Add transmission for actuation -->
        <transmission name="${prefix}_trans">
            <type>transmission_interface/SimpleTransmission</type>
            <joint name="${prefix}_extension">
                <hardwareInterface>hardware_interface/EffortJointInterface</hardwareInterface>
            </joint>
            <actuator name="${prefix}_motor">
                <mechanicalReduction>1</mechanicalReduction>
            </actuator>
        </transmission>
    </xacro:macro>
</robot>