<?xml version="1.0"?>
<robot xmlns:xacro="http://www.ros.org/wiki/xacro" name="simple_arm">

    <!-- Colors -->
    <material name="blue">
        <color rgba="0 0 0.8 1"/>
    </material>
    <material name="red">
        <color rgba="0.8 0 0 1"/>
    </material>
    <material name="green">
        <color rgba="0 0.8 0 1"/>
    </material>

    <!-- Base Link -->
    <link name="world"/>
    
    <link name="base_link">
        <visual>
            <geometry>
                <cylinder length="0.2" radius="0.2"/>
            </geometry>
            <material name="blue"/>
        </visual>
        <collision>
            <geometry>
                <cylinder length="0.2" radius="0.2"/>
            </geometry>
        </collision>
        <inertial>
            <mass value="1"/>
            <inertia ixx="0.02" iyy="0.02" izz="0.02" ixy="0" ixz="0" iyz="0"/>
        </inertial>
    </link>

    <joint name="world_joint" type="fixed">
        <parent link="world"/>
        <child link="base_link"/>
        <origin xyz="0 0 0.1"/>
    </joint>

    <!-- Link 1 -->
    <link name="link1">
        <visual>
            <geometry>
                <box size="0.1 0.1 0.5"/>
            </geometry>
            <origin xyz="0 0 0.25"/>
            <material name="red"/>
        </visual>
        <collision>
            <geometry>
                <box size="0.1 0.1 0.5"/>
            </geometry>
            <origin xyz="0 0 0.25"/>
        </collision>
        <inertial>
            <mass value="1"/>
            <origin xyz="0 0 0.25"/>
            <inertia ixx="0.02" iyy="0.02" izz="0.01" ixy="0" ixz="0" iyz="0"/>
        </inertial>
    </link>

    <!-- Joint 1 -->
    <joint name="joint1" type="revolute">
        <parent link="base_link"/>
        <child link="link1"/>
        <origin xyz="0 0 0.1"/>
        <axis xyz="0 0 1"/>
        <limit lower="-3.14" upper="3.14" effort="100" velocity="100"/>
        <dynamics damping="0.1"/>
    </joint>

    <!-- Link 2 -->
    <link name="link2">
        <visual>
            <geometry>
                <box size="0.1 0.1 0.5"/>
            </geometry>
            <origin xyz="0 0 0.25"/>
            <material name="green"/>
        </visual>
        <collision>
            <geometry>
                <box size="0.1 0.1 0.5"/>
            </geometry>
            <origin xyz="0 0 0.25"/>
        </collision>
        <inertial>
            <mass value="1"/>
            <origin xyz="0 0 0.25"/>
            <inertia ixx="0.02" iyy="0.02" izz="0.01" ixy="0" ixz="0" iyz="0"/>
        </inertial>
    </link>

    <!-- Joint 2 -->
    <joint name="joint2" type="revolute">
        <parent link="link1"/>
        <child link="link2"/>
        <origin xyz="0 0 0.5"/>
        <axis xyz="0 1 0"/>
        <limit lower="-3.14" upper="3.14" effort="100" velocity="100"/>
        <dynamics damping="0.1"/>
    </joint>

    <!-- Link 3 (End Effector) -->
    <link name="link3">
        <visual>
            <geometry>
                <box size="0.1 0.1 0.2"/>
            </geometry>
            <origin xyz="0 0 0.1"/>
            <material name="blue"/>
        </visual>
        <collision>
            <geometry>
                <box size="0.1 0.1 0.2"/>
            </geometry>
            <origin xyz="0 0 0.1"/>
        </collision>
        <inertial>
            <mass value="0.5"/>
            <origin xyz="0 0 0.1"/>
            <inertia ixx="0.01" iyy="0.01" izz="0.005" ixy="0" ixz="0" iyz="0"/>
        </inertial>
    </link>

    <!-- Joint 3 -->
    <joint name="joint3" type="revolute">
        <parent link="link2"/>
        <child link="link3"/>
        <origin xyz="0 0 0.5"/>
        <axis xyz="0 1 0"/>
        <limit lower="-3.14" upper="3.14" effort="100" velocity="100"/>
        <dynamics damping="0.1"/>
    </joint>

    <!-- Gazebo plugins -->
    <gazebo>
        <plugin filename="gz-sim-joint-state-publisher-system"
                name="gz::sim::systems::JointStatePublisher">
            <joint_name>joint1</joint_name>
            <joint_name>joint2</joint_name>
            <joint_name>joint3</joint_name>
        </plugin>
        
        <plugin filename="gz-sim-physics-system"
                name="gz::sim::systems::Physics">
            <engine>dart</engine>
            <dart>
                <solver>
                    <solver_type>dantzig</solver_type>
                </solver>
            </dart>
            <update_rate>1000</update_rate>
        </plugin>
    </gazebo>

    <!-- Material properties for Gazebo -->
    <gazebo reference="base_link">
        <material>Gazebo/Blue</material>
    </gazebo>

    <gazebo reference="link1">
        <material>Gazebo/Red</material>
    </gazebo>

    <gazebo reference="link2">
        <material>Gazebo/Green</material>
    </gazebo>

    <gazebo reference="link3">
        <material>Gazebo/Blue</material>
    </gazebo>

</robot>